<sdf version='1.7'>
  <world name='default'>
    <light name='sun' type='directional'>
      <cast_shadows>1</cast_shadows>
      <pose>0 0 10 0 -0 0</pose>
      <diffuse>0.8 0.8 0.8 1</diffuse>
      <specular>0.2 0.2 0.2 1</specular>
      <attenuation>
        <range>1000</range>
        <constant>0.9</constant>
        <linear>0.01</linear>
        <quadratic>0.001</quadratic>
      </attenuation>
      <direction>-0.5 0.1 -0.9</direction>
      <spot>
        <inner_angle>0</inner_angle>
        <outer_angle>0</outer_angle>
        <falloff>0</falloff>
      </spot>
    </light>
    <model name='ground_plane'>
      <static>1</static>
      <link name='link'>
        <collision name='collision'>
          <geometry>
            <plane>
              <normal>0 0 1</normal>
              <size>100 100</size>
            </plane>
          </geometry>
          <surface>
            <friction>
              <ode>
                <mu>100</mu>
                <mu2>50</mu2>
              </ode>
              <torsional>
                <ode/>
              </torsional>
            </friction>
            <contact>
              <ode/>
            </contact>
            <bounce/>
          </surface>
          <max_contacts>10</max_contacts>
        </collision>
        <visual name='visual'>
          <cast_shadows>0</cast_shadows>
          <geometry>
            <plane>
              <normal>0 0 1</normal>
              <size>100 100</size>
            </plane>
          </geometry>
          <material>
            <script>
              <uri>file://media/materials/scripts/gazebo.material</uri>
              <name>Gazebo/Grey</name>
            </script>
          </material>
        </visual>
        <self_collide>0</self_collide>
        <enable_wind>0</enable_wind>
        <kinematic>0</kinematic>
      </link>
    </model>
    <gravity>0 0 -9.8</gravity>
    <magnetic_field>6e-06 2.3e-05 -4.2e-05</magnetic_field>
    <atmosphere type='adiabatic'/>
    <physics type='ode'>
      <max_step_size>0.001</max_step_size>
      <real_time_factor>1</real_time_factor>
      <real_time_update_rate>1000</real_time_update_rate>
    </physics>
    <scene>
      <ambient>0.4 0.4 0.4 1</ambient>
      <background>0.7 0.7 0.7 1</background>
      <shadows>1</shadows>
    </scene>
    <wind/>
    <spherical_coordinates>
      <surface_model>EARTH_WGS84</surface_model>
      <latitude_deg>0</latitude_deg>
      <longitude_deg>0</longitude_deg>
      <elevation>0</elevation>
      <heading_deg>0</heading_deg>
    </spherical_coordinates>
    <state world_name='default'>
      <sim_time>45 398000000</sim_time>
      <real_time>45 709955098</real_time>
      <wall_time>1687014568 531237723</wall_time>
      <iterations>45398</iterations>
      <model name='ground_plane'>
        <pose>0 0 0 0 -0 0</pose>
        <scale>1 1 1</scale>
        <link name='link'>
          <pose>0 0 0 0 -0 0</pose>
          <velocity>0 0 0 0 -0 0</velocity>
          <acceleration>0 0 0 0 -0 0</acceleration>
          <wrench>0 0 0 0 -0 0</wrench>
        </link>
      </model>
      <model name='unit_box'>
        <pose>4.01749 0.590038 0.5 0 -0 0</pose>
        <scale>1 1 1</scale>
        <link name='link'>
          <pose>4.01749 0.590038 0.5 0 -0 0</pose>
          <velocity>0 0 0 0 -0 0</velocity>
          <acceleration>-0.004709 -9.78112 9.78158 0.712677 -0.009414 -4.3e-05</acceleration>
          <wrench>-0.004709 -9.78112 9.78158 0 -0 0</wrench>
        </link>
      </model>
      <model name='velodyne_hdl-32'>
        <pose>0.526044 0.614918 3e-06 -0 -1.2e-05 -1.3e-05</pose>
        <scale>1 1 1</scale>
        <link name='link_0'>
          <pose>0.526039 0.614918 0.400003 -0 -1.2e-05 -1.3e-05</pose>
          <velocity>0.09739 0.025216 -0.001103 -0.005602 -0.007074 -0.032798</velocity>
          <acceleration>-1.37016 4.11941 -2.22668 -1.77187 -1.51979 -3.00511</acceleration>
          <wrench>-1.34003 4.02882 -2.17771 0 -0 0</wrench>
        </link>
        <link name='link_1'>
          <pose>1.23286 0.041031 0.300012 1.57006 1.44046 -0.00074</pose>
          <velocity>0.079259 0.00159 0.00714 -0.005312 0.277847 -0.032801</velocity>
          <acceleration>0.109821 3.21395 14.2555 -1.47529 0.854274 -3.00763</acceleration>
          <wrench>0.109821 3.21395 14.2555 0 -0 0</wrench>
        </link>
        <link name='link_1_clone'>
          <pose>1.23288 1.18879 0.300012 1.5687 1.52472 -0.002109</pose>
          <velocity>0.116909 0.001515 0.0007 -0.005561 0.404191 -0.032829</velocity>
          <acceleration>-0.041205 3.13772 1.39418 1.42064 -0.922686 0.12215</acceleration>
          <wrench>-0.041205 3.13772 1.39418 0 -0 0</wrench>
        </link>
        <link name='link_2'>
          <pose>-0.280789 0.614929 0.199993 -3.13792 0.679926 -3.13567</pose>
          <velocity>0.098802 0.050571 -0.006806 -0.243883 0.486739 -0</velocity>
          <acceleration>1.45416 1.79471 -13.6634 -0 -0 -0</acceleration>
          <wrench>1.45416 1.79471 -13.6634 0 -0 0</wrench>
        </link>
        <model name='depth_camera'>
          <pose>0.698731 0.615751 0.682741 0 -0 0</pose>
          <scale>1 1 1</scale>
          <link name='link'>
            <pose>1.2295 0.615643 0.732681 0 -5.6e-05 -1.1e-05</pose>
            <velocity>0.097158 0.000186 -0.000475 -0.006382 -0.00866 -0.030933</velocity>
            <acceleration>-1.98649 0.323607 -0.847054 -0.165701 1.51723 -2.4261</acceleration>
            <wrench>-0.198649 0.032361 -0.084705 0 -0 0</wrench>
          </link>
        </model>
        <model name='velodyne'>
          <pose>-0.040381 0.617535 1.89796 0 -0 0</pose>
          <scale>1 1 1</scale>
          <link name='base'>
            <pose>0.490421 0.617406 1.9273 -9e-06 -2e-05 -1.3e-05</pose>
            <velocity>0.096892 0.025412 -0.001012 -0.008157 -0.009886 -0.032861</velocity>
            <acceleration>-0.260895 0.310701 -1.96132 -1.09763 -1.51856 -3.13881</acceleration>
            <wrench>-0.313074 0.372841 -2.35359 0 -0 0</wrench>
          </link>
          <link name='top'>
            <pose>0.490419 0.617407 1.99342 -9e-06 -2.1e-05 2e-06</pose>
            <velocity>0.096251 0.02594 -0.001014 -0.008184 -0.009918 1e-06</velocity>
            <acceleration>-1.58847 1.39676 -1.96307 -1.15632 -1.44736 3.14143</acceleration>
            <wrench>-0.158847 0.139676 -0.196307 0 -0 0</wrench>
          </link>
        </model>
      </model>
      <light name='sun'>
        <pose>0 0 10 0 -0 0</pose>
      </light>
    </state>
    <gui fullscreen='0'>
      <camera name='user_camera'>
        <pose>8.52154 -4.34153 3.71488 0 0.325881 2.41163</pose>
        <view_controller>orbit</view_controller>
        <projection_type>perspective</projection_type>
      </camera>
    </gui>
    <audio>
      <device>default</device>
    </audio>
    <model name='velodyne_hdl-32'>
      <link name='link_0'>
        <inertial>
          <mass>0.978008</mass>
          <inertia>
            <ixx>0.122564</ixx>
            <ixy>0</ixy>
            <ixz>0</ixz>
            <iyy>0.407773</iyy>
            <iyz>0</iyz>
            <izz>0.472213</izz>
          </inertia>
          <pose>0 0 0 0 -0 0</pose>
        </inertial>
        <pose>0 0 0.4 0 -0 0</pose>
        <gravity>1</gravity>
        <self_collide>0</self_collide>
        <kinematic>0</kinematic>
        <enable_wind>0</enable_wind>
        <visual name='visual'>
          <pose>0 0 0 0 -0 0</pose>
          <geometry>
            <box>
              <size>2.01366 0.897702 0.541504</size>
            </box>
          </geometry>
          <material>
            <lighting>1</lighting>
            <script>
              <uri>file://media/materials/scripts/gazebo.material</uri>
              <name>Gazebo/Grey</name>
            </script>
            <shader type='pixel'>
              <normal_map>__default__</normal_map>
            </shader>
            <ambient>0.3 0.3 0.3 1</ambient>
            <diffuse>0.7 0.7 0.7 1</diffuse>
            <specular>0.01 0.01 0.01 1</specular>
            <emissive>0 0 0 1</emissive>
          </material>
          <transparency>0</transparency>
          <cast_shadows>1</cast_shadows>
        </visual>
        <collision name='collision'>
          <laser_retro>0</laser_retro>
          <max_contacts>10</max_contacts>
          <pose>0 0 0 0 -0 0</pose>
          <geometry>
            <box>
              <size>2.01366 0.897702 0.541504</size>
            </box>
          </geometry>
          <surface>
            <friction>
              <ode>
                <mu>1</mu>
                <mu2>1</mu2>
                <fdir1>0 0 0</fdir1>
                <slip1>0</slip1>
                <slip2>0</slip2>
              </ode>
              <torsional>
                <coefficient>1</coefficient>
                <patch_radius>0</patch_radius>
                <surface_radius>0</surface_radius>
                <use_patch_radius>1</use_patch_radius>
                <ode>
                  <slip>0</slip>
                </ode>
              </torsional>
            </friction>
            <bounce>
              <restitution_coefficient>0</restitution_coefficient>
              <threshold>1e+06</threshold>
            </bounce>
            <contact>
              <collide_without_contact>0</collide_without_contact>
              <collide_without_contact_bitmask>1</collide_without_contact_bitmask>
              <collide_bitmask>1</collide_bitmask>
              <ode>
                <soft_cfm>0</soft_cfm>
                <soft_erp>0.2</soft_erp>
                <kp>1e+13</kp>
                <kd>1</kd>
                <max_vel>0.01</max_vel>
                <min_depth>0</min_depth>
              </ode>
              <bullet>
                <split_impulse>1</split_impulse>
                <split_impulse_penetration_threshold>-0.01</split_impulse_penetration_threshold>
                <soft_cfm>0</soft_cfm>
                <soft_erp>0.2</soft_erp>
                <kp>1e+13</kp>
                <kd>1</kd>
              </bullet>
            </contact>
          </surface>
        </collision>
      </link>
      <link name='link_1'>
        <inertial>
          <mass>1</mass>
          <inertia>
            <ixx>0.145833</ixx>
            <ixy>0</ixy>
            <ixz>0</ixz>
            <iyy>0.145833</iyy>
            <iyz>0</iyz>
            <izz>0.125</izz>
          </inertia>
          <pose>0 0 0 0 -0 0</pose>
        </inertial>
        <pose>0.70683 -0.573879 0.3 1.5707 -0 0</pose>
        <gravity>1</gravity>
        <self_collide>0</self_collide>
        <kinematic>0</kinematic>
        <enable_wind>0</enable_wind>
        <visual name='visual'>
          <pose>0 0 0 0 -0 0</pose>
          <geometry>
            <cylinder>
              <radius>0.3</radius>
              <length>0.25</length>
            </cylinder>
          </geometry>
          <material>
            <lighting>1</lighting>
            <script>
              <uri>file://media/materials/scripts/gazebo.material</uri>
              <name>Gazebo/Grey</name>
            </script>
            <shader type='pixel'>
              <normal_map>__default__</normal_map>
            </shader>
            <ambient>0.3 0.3 0.3 1</ambient>
            <diffuse>0.7 0.7 0.7 1</diffuse>
            <specular>0.01 0.01 0.01 1</specular>
            <emissive>0 0 0 1</emissive>
          </material>
          <transparency>0</transparency>
          <cast_shadows>1</cast_shadows>
        </visual>
        <collision name='collision'>
          <laser_retro>0</laser_retro>
          <max_contacts>10</max_contacts>
          <pose>0 0 0 0 -0 0</pose>
          <geometry>
            <cylinder>
              <radius>0.3</radius>
              <length>0.25</length>
            </cylinder>
          </geometry>
          <surface>
            <friction>
              <ode>
                <mu>1</mu>
                <mu2>1</mu2>
                <fdir1>0 0 0</fdir1>
                <slip1>0</slip1>
                <slip2>0</slip2>
              </ode>
              <torsional>
                <coefficient>1</coefficient>
                <patch_radius>0</patch_radius>
                <surface_radius>0</surface_radius>
                <use_patch_radius>1</use_patch_radius>
                <ode>
                  <slip>0</slip>
                </ode>
              </torsional>
            </friction>
            <bounce>
              <restitution_coefficient>0</restitution_coefficient>
              <threshold>1e+06</threshold>
            </bounce>
            <contact>
              <collide_without_contact>0</collide_without_contact>
              <collide_without_contact_bitmask>1</collide_without_contact_bitmask>
              <collide_bitmask>1</collide_bitmask>
              <ode>
                <soft_cfm>0</soft_cfm>
                <soft_erp>0.2</soft_erp>
                <kp>1e+13</kp>
                <kd>1</kd>
                <max_vel>0.01</max_vel>
                <min_depth>0</min_depth>
              </ode>
              <bullet>
                <split_impulse>1</split_impulse>
                <split_impulse_penetration_threshold>-0.01</split_impulse_penetration_threshold>
                <soft_cfm>0</soft_cfm>
                <soft_erp>0.2</soft_erp>
                <kp>1e+13</kp>
                <kd>1</kd>
              </bullet>
            </contact>
          </surface>
        </collision>
      </link>
      <link name='link_1_clone'>
        <inertial>
          <mass>1</mass>
          <inertia>
            <ixx>0.145833</ixx>
            <ixy>0</ixy>
            <ixz>0</ixz>
            <iyy>0.145833</iyy>
            <iyz>0</iyz>
            <izz>0.125</izz>
          </inertia>
          <pose>0 0 0 0 -0 0</pose>
        </inertial>
        <pose>0.70683 0.573879 0.3 1.5707 -0 0</pose>
        <gravity>1</gravity>
        <self_collide>0</self_collide>
        <kinematic>0</kinematic>
        <enable_wind>0</enable_wind>
        <visual name='visual'>
          <pose>0 0 0 0 -0 0</pose>
          <geometry>
            <cylinder>
              <radius>0.3</radius>
              <length>0.25</length>
            </cylinder>
          </geometry>
          <material>
            <lighting>1</lighting>
            <script>
              <uri>file://media/materials/scripts/gazebo.material</uri>
              <name>Gazebo/Grey</name>
            </script>
            <shader type='pixel'>
              <normal_map>__default__</normal_map>
            </shader>
            <ambient>0.3 0.3 0.3 1</ambient>
            <diffuse>0.7 0.7 0.7 1</diffuse>
            <specular>0.01 0.01 0.01 1</specular>
            <emissive>0 0 0 1</emissive>
          </material>
          <transparency>0</transparency>
          <cast_shadows>1</cast_shadows>
        </visual>
        <collision name='collision'>
          <laser_retro>0</laser_retro>
          <max_contacts>10</max_contacts>
          <pose>0 0 0 0 -0 0</pose>
          <geometry>
            <cylinder>
              <radius>0.3</radius>
              <length>0.25</length>
            </cylinder>
          </geometry>
          <surface>
            <friction>
              <ode>
                <mu>1</mu>
                <mu2>1</mu2>
                <fdir1>0 0 0</fdir1>
                <slip1>0</slip1>
                <slip2>0</slip2>
              </ode>
              <torsional>
                <coefficient>1</coefficient>
                <patch_radius>0</patch_radius>
                <surface_radius>0</surface_radius>
                <use_patch_radius>1</use_patch_radius>
                <ode>
                  <slip>0</slip>
                </ode>
              </torsional>
            </friction>
            <bounce>
              <restitution_coefficient>0</restitution_coefficient>
              <threshold>1e+06</threshold>
            </bounce>
            <contact>
              <collide_without_contact>0</collide_without_contact>
              <collide_without_contact_bitmask>1</collide_without_contact_bitmask>
              <collide_bitmask>1</collide_bitmask>
              <ode>
                <soft_cfm>0</soft_cfm>
                <soft_erp>0.2</soft_erp>
                <kp>1e+13</kp>
                <kd>1</kd>
                <max_vel>0.01</max_vel>
                <min_depth>0</min_depth>
              </ode>
              <bullet>
                <split_impulse>1</split_impulse>
                <split_impulse_penetration_threshold>-0.01</split_impulse_penetration_threshold>
                <soft_cfm>0</soft_cfm>
                <soft_erp>0.2</soft_erp>
                <kp>1e+13</kp>
                <kd>1</kd>
              </bullet>
            </contact>
          </surface>
        </collision>
      </link>
      <link name='link_2'>
        <inertial>
          <mass>1</mass>
          <inertia>
            <ixx>0.1</ixx>
            <ixy>0</ixy>
            <ixz>0</ixz>
            <iyy>0.1</iyy>
            <iyz>0</iyz>
            <izz>0.1</izz>
          </inertia>
          <pose>0 0 0 0 -0 0</pose>
        </inertial>
        <pose>-0.80683 0 0.2 0 -0 0</pose>
        <gravity>1</gravity>
        <self_collide>0</self_collide>
        <kinematic>0</kinematic>
        <enable_wind>0</enable_wind>
        <visual name='visual'>
          <pose>0 0 0 0 -0 0</pose>
          <geometry>
            <sphere>
              <radius>0.2</radius>
            </sphere>
          </geometry>
          <material>
            <lighting>1</lighting>
            <script>
              <uri>file://media/materials/scripts/gazebo.material</uri>
              <name>Gazebo/Grey</name>
            </script>
            <shader type='pixel'>
              <normal_map>__default__</normal_map>
            </shader>
            <ambient>0.3 0.3 0.3 1</ambient>
            <diffuse>0.7 0.7 0.7 1</diffuse>
            <specular>0.01 0.01 0.01 1</specular>
            <emissive>0 0 0 1</emissive>
          </material>
          <transparency>0</transparency>
          <cast_shadows>1</cast_shadows>
        </visual>
        <collision name='collision'>
          <laser_retro>0</laser_retro>
          <max_contacts>10</max_contacts>
          <pose>0 0 0 0 -0 0</pose>
          <geometry>
            <sphere>
              <radius>0.2</radius>
            </sphere>
          </geometry>
          <surface>
            <friction>
              <ode>
                <mu>1</mu>
                <mu2>1</mu2>
                <fdir1>0 0 0</fdir1>
                <slip1>0</slip1>
                <slip2>0</slip2>
              </ode>
              <torsional>
                <coefficient>1</coefficient>
                <patch_radius>0</patch_radius>
                <surface_radius>0</surface_radius>
                <use_patch_radius>1</use_patch_radius>
                <ode>
                  <slip>0</slip>
                </ode>
              </torsional>
            </friction>
            <bounce>
              <restitution_coefficient>0</restitution_coefficient>
              <threshold>1e+06</threshold>
            </bounce>
            <contact>
              <collide_without_contact>0</collide_without_contact>
              <collide_without_contact_bitmask>1</collide_without_contact_bitmask>
              <collide_bitmask>1</collide_bitmask>
              <ode>
                <soft_cfm>0</soft_cfm>
                <soft_erp>0.2</soft_erp>
                <kp>1e+13</kp>
                <kd>1</kd>
                <max_vel>0.01</max_vel>
                <min_depth>0</min_depth>
              </ode>
              <bullet>
                <split_impulse>1</split_impulse>
                <split_impulse_penetration_threshold>-0.01</split_impulse_penetration_threshold>
                <soft_cfm>0</soft_cfm>
                <soft_erp>0.2</soft_erp>
                <kp>1e+13</kp>
                <kd>1</kd>
              </bullet>
            </contact>
          </surface>
        </collision>
      </link>
      <model name='depth_camera'>
        <link name='link'>
          <pose>0 0 0.05 0 -0 0</pose>
          <inertial>
            <mass>0.1</mass>
            <inertia>
              <ixx>0.000166667</ixx>
              <iyy>0.000166667</iyy>
              <izz>0.000166667</izz>
              <ixy>0</ixy>
              <ixz>0</ixz>
              <iyz>0</iyz>
            </inertia>
            <pose>0 0 0 0 -0 0</pose>
          </inertial>
          <collision name='collision'>
            <geometry>
              <box>
                <size>0.1 0.1 0.1</size>
              </box>
            </geometry>
            <max_contacts>10</max_contacts>
            <surface>
              <contact>
                <ode/>
              </contact>
              <bounce/>
              <friction>
                <torsional>
                  <ode/>
                </torsional>
                <ode/>
              </friction>
            </surface>
          </collision>
          <visual name='visual'>
            <geometry>
              <box>
                <size>0.1 0.1 0.1</size>
              </box>
            </geometry>
          </visual>
          <sensor name='camera' type='depth'>
            <camera>
              <horizontal_fov>1.047</horizontal_fov>
              <image>
                <width>320</width>
                <height>240</height>
              </image>
              <clip>
                <near>0.1</near>
                <far>100</far>
              </clip>
            </camera>
            <always_on>1</always_on>
            <update_rate>30</update_rate>
            <visualize>1</visualize>
          </sensor>
          <self_collide>0</self_collide>
          <enable_wind>0</enable_wind>
          <kinematic>0</kinematic>
        </link>
        <pose>0.703483 0.000736 0.682741 0 -0 0</pose>
      </model>
      <model name='velodyne'>
        <link name='base'>
          <pose>0 0 0.029335 0 -0 0</pose>
          <inertial>
            <mass>1.2</mass>
            <inertia>
              <ixx>0.00108747</ixx>
              <iyy>0.00108747</iyy>
              <izz>0.00109244</izz>
              <ixy>0</ixy>
              <ixz>0</ixz>
              <iyz>0</iyz>
            </inertia>
            <pose>0 0 0 0 -0 0</pose>
          </inertial>
          <collision name='base_collision'>
            <geometry>
              <cylinder>
                <radius>0.04267</radius>
                <length>0.05867</length>
              </cylinder>
            </geometry>
            <max_contacts>10</max_contacts>
            <surface>
              <contact>
                <ode/>
              </contact>
              <bounce/>
              <friction>
                <torsional>
                  <ode/>
                </torsional>
                <ode/>
              </friction>
            </surface>
          </collision>
          <visual name='base_visual'>
            <pose>0 0 -0.029335 0 -0 0</pose>
            <geometry>
              <mesh>
                <uri>model://velodyne_hdl32/meshes/velodyne_base.dae</uri>
              </mesh>
            </geometry>
          </visual>
          <self_collide>0</self_collide>
          <enable_wind>0</enable_wind>
          <kinematic>0</kinematic>
        </link>
        <link name='top'>
          <pose>0 0 0.095455 0 -0 0</pose>
          <inertial>
            <mass>0.1</mass>
            <inertia>
              <ixx>9.0623e-05</ixx>
              <iyy>9.0623e-05</iyy>
              <izz>9.1036e-05</izz>
              <ixy>0</ixy>
              <ixz>0</ixz>
              <iyz>0</iyz>
            </inertia>
            <pose>0 0 0 0 -0 0</pose>
          </inertial>
          <collision name='top_collision'>
            <geometry>
              <cylinder>
                <radius>0.04267</radius>
                <length>0.07357</length>
              </cylinder>
            </geometry>
            <max_contacts>10</max_contacts>
            <surface>
              <contact>
                <ode/>
              </contact>
              <bounce/>
              <friction>
                <torsional>
                  <ode/>
                </torsional>
                <ode/>
              </friction>
            </surface>
          </collision>
          <visual name='top_visual'>
            <pose>0 0 -0.037679 0 -0 1.5707</pose>
            <geometry>
              <mesh>
                <uri>model://velodyne_hdl32/meshes/velodyne_top.dae</uri>
              </mesh>
            </geometry>
          </visual>
          <sensor name='sensor' type='ray'>
            <pose>0 0 -0.004645 1.5707 -0 0</pose>
            <visualize>1</visualize>
            <update_rate>30</update_rate>
            <ray>
              <noise>
                <type>gaussian</type>
                <mean>0</mean>
                <stddev>0.1</stddev>
              </noise>
              <scan>
                <horizontal>
                  <samples>32</samples>
                  <resolution>1</resolution>
                  <min_angle>-0.535292</min_angle>
                  <max_angle>0.186227</max_angle>
                </horizontal>
                <vertical>
                  <samples>1</samples>
                  <min_angle>0</min_angle>
                  <max_angle>0</max_angle>
                </vertical>
              </scan>
              <range>
                <min>0.1</min>
                <max>70</max>
                <resolution>0.02</resolution>
              </range>
            </ray>
          </sensor>
          <self_collide>0</self_collide>
          <enable_wind>0</enable_wind>
          <kinematic>0</kinematic>
        </link>
        <joint name='joint' type='revolute'>
          <pose>0 0 -0.036785 0 -0 0</pose>
          <parent>base</parent>
          <child>top</child>
          <axis>
            <xyz>0 0 1</xyz>
            <limit>
              <lower>-1e+16</lower>
              <upper>1e+16</upper>
            </limit>
            <dynamics>
              <spring_reference>0</spring_reference>
              <spring_stiffness>0</spring_stiffness>
            </dynamics>
          </axis>
        </joint>
        <pose>-0.035629 0.00252 1.89796 0 -0 0</pose>
      </model>
      <joint name='link_0_JOINT_0' type='revolute'>
        <parent>link_0</parent>
        <child>link_1_clone</child>
        <pose>0 0 0 0 -0 0</pose>
        <axis>
          <xyz>0 0 1</xyz>
          <limit>
            <lower>-1.79769e+308</lower>
            <upper>1.79769e+308</upper>
            <effort>-1</effort>
            <velocity>-1</velocity>
          </limit>
          <dynamics>
            <spring_reference>0</spring_reference>
            <spring_stiffness>0</spring_stiffness>
            <damping>0</damping>
            <friction>0</friction>
          </dynamics>
        </axis>
        <physics>
          <ode>
            <limit>
              <cfm>0</cfm>
              <erp>0.2</erp>
            </limit>
            <suspension>
              <cfm>0</cfm>
              <erp>0.2</erp>
            </suspension>
          </ode>
        </physics>
      </joint>
      <joint name='link_0_JOINT_1' type='revolute'>
        <parent>link_0</parent>
        <child>link_1</child>
        <pose>0 0 0 0 -0 0</pose>
        <axis>
          <xyz>0 0 1</xyz>
          <limit>
            <lower>-1.79769e+308</lower>
            <upper>1.79769e+308</upper>
            <effort>-1</effort>
            <velocity>-1</velocity>
          </limit>
          <dynamics>
            <spring_reference>0</spring_reference>
            <spring_stiffness>0</spring_stiffness>
            <damping>0</damping>
            <friction>0</friction>
          </dynamics>
        </axis>
        <physics>
          <ode>
            <limit>
              <cfm>0</cfm>
              <erp>0.2</erp>
            </limit>
            <suspension>
              <cfm>0</cfm>
              <erp>0.2</erp>
            </suspension>
          </ode>
        </physics>
      </joint>
      <joint name='link_0_JOINT_2' type='ball'>
        <parent>link_0</parent>
        <child>link_2</child>
        <pose>0 0 0 0 -0 0</pose>
        <physics>
          <ode>
            <limit>
              <cfm>0</cfm>
              <erp>0.2</erp>
            </limit>
            <suspension>
              <cfm>0</cfm>
              <erp>0.2</erp>
            </suspension>
          </ode>
        </physics>
      </joint>
      <joint name='link_0_JOINT_3' type='fixed'>
        <parent>link_0</parent>
        <child>depth_camera::link</child>
        <pose>0 0 0 0 -0 0</pose>
        <physics>
          <ode>
            <limit>
              <cfm>0</cfm>
              <erp>0.2</erp>
            </limit>
            <suspension>
              <cfm>0</cfm>
              <erp>0.2</erp>
            </suspension>
          </ode>
        </physics>
      </joint>
      <joint name='link_0_JOINT_6' type='fixed'>
        <parent>link_0</parent>
        <child>velodyne::base</child>
        <pose>0 0 0 0 -0 0</pose>
        <physics>
          <ode>
            <limit>
              <cfm>0</cfm>
              <erp>0.2</erp>
            </limit>
            <suspension>
              <cfm>0</cfm>
              <erp>0.2</erp>
            </suspension>
          </ode>
        </physics>
      </joint>
      <static>0</static>
      <allow_auto_disable>1</allow_auto_disable>
      <plugin name='follower' filename='libFollowerPlugin.so'/>
      <pose>0.795252 0.666943 0 0 -0 0</pose>
    </model>
    <model name='unit_box'>
      <pose>4.01749 0.590038 0.5 0 -0 0</pose>
      <link name='link'>
        <inertial>
          <mass>1</mass>
          <inertia>
            <ixx>0.166667</ixx>
            <ixy>0</ixy>
            <ixz>0</ixz>
            <iyy>0.166667</iyy>
            <iyz>0</iyz>
            <izz>0.166667</izz>
          </inertia>
          <pose>0 0 0 0 -0 0</pose>
        </inertial>
        <collision name='collision'>
          <geometry>
            <box>
              <size>1 1 1</size>
            </box>
          </geometry>
          <max_contacts>10</max_contacts>
          <surface>
            <contact>
              <ode/>
            </contact>
            <bounce/>
            <friction>
              <torsional>
                <ode/>
              </torsional>
              <ode/>
            </friction>
          </surface>
        </collision>
        <visual name='visual'>
          <geometry>
            <box>
              <size>1 1 1</size>
            </box>
          </geometry>
          <material>
            <script>
              <name>Gazebo/Grey</name>
              <uri>file://media/materials/scripts/gazebo.material</uri>
            </script>
          </material>
        </visual>
        <self_collide>0</self_collide>
        <enable_wind>0</enable_wind>
        <kinematic>0</kinematic>
      </link>
    </model>
    <joint type='revolute' name='joint'>
      <pose>0 0 -0.036785 0 0 0</pose>
      <parent>base</parent>
      <child>top</child>
      <axis>
        <xyz>0 0 1</xyz>
        <limit>
          <lower>-10000000000000000</lower>
          <upper>10000000000000000</upper>
        </limit>
      </axis>
    </joint>
  </world>
</sdf>
